<?xml version="1.0" encoding="utf-8"?>
<!-- This URDF was automatically created by SolidWorks to URDF Exporter! Originally created by Stephen Brawner (brawner@gmail.com) 
     Commit Version: 1.6.0-1-g15f4949  Build Version: 1.6.7594.29634
     For more information, please see http://wiki.ros.org/sw_urdf_exporter -->
<robot name="jetcobot">
  <link name="dummy"/>
  <joint name="dummy_joint" type="fixed">
    <parent link="dummy"/>
    <child link="base_link"/>
  </joint>
  <link
    name="base_link">
    <inertial>
      <origin
        xyz="-0.0131083790012654 6.69302038809875E-06 0.0354087419202998"
        rpy="0 0 0" />
      <mass
        value="0.492874947350045" />
      <inertia
        ixx="0.000404279561956854"
        ixy="9.00304029145705E-08"
        ixz="-1.87890310458906E-05"
        iyy="0.000608346288236137"
        iyz="4.80299375571781E-08"
        izz="0.000624652394733672" />
    </inertial>
    <visual>
      <origin
        xyz="0 0 0"
        rpy="0 0 0" />
      <geometry>
        <mesh
          filename="package://jetcobot_description/meshes/base_link.STL" />
      </geometry>
      <material
        name="">
        <color
          rgba="1 1 1 1" />
      </material>
    </visual>
    <collision>
      <origin
        xyz="0 0 0"
        rpy="0 0 0" />
      <geometry>
        <mesh
          filename="package://jetcobot_description/meshes/base_link.STL" />
      </geometry>
    </collision>
  </link>
  <link
    name="1_Link">
    <inertial>
      <origin
        xyz="-1.31131235135193E-05 -0.00680904441821013 0.0422096528553218"
        rpy="0 0 0" />
      <mass
        value="0.0362552727733653" />
      <inertia
        ixx="2.91075748915876E-05"
        ixy="6.17235351914783E-09"
        ixz="-9.05544995948064E-09"
        iyy="3.1419883802157E-05"
        iyz="7.56958694374969E-06"
        izz="1.50541827786635E-05" />
    </inertial>
    <visual>
      <origin
        xyz="0 0 0"
        rpy="0 0 0" />
      <geometry>
        <mesh
          filename="package://jetcobot_description/meshes/LInk_1.stl" />
      </geometry>
      <material
        name="">
        <color
          rgba="1 1 1 1" />
      </material>
    </visual>
    <collision>
      <origin
        xyz="0 0 0"
        rpy="0 0 0" />
      <geometry>
        <mesh
          filename="package://jetcobot_description/meshes/LInk_1.stl" />
      </geometry>
    </collision>
  </link>
  <joint
    name="1_Joint"
    type="revolute">
    <origin
      xyz="0 0 0.074520000000001"
      rpy="0 0 0" />
    <parent
      link="base_link" />
    <child
      link="1_Link" />
    <axis
      xyz="0 0 1" />
    <limit
      lower="-2.87"
      upper="2.87"
      effort="0"
      velocity="0" />
  </joint>
  <link
    name="2_Link">
    <inertial>
      <origin
        xyz="-7.75613648330207E-06 -0.0235034548911008 0.0516000320310254"
        rpy="0 0 0" />
      <mass
        value="0.0668252611526333" />
      <inertia
        ixx="0.00015843232374682"
        ixy="-1.60643645992328E-09"
        ixz="8.77346086416886E-09"
        iyy="0.00016705510176789"
        iyz="-5.95622238422236E-07"
        izz="2.06389799675899E-05" />
    </inertial>
    <visual>
      <origin
        xyz="0 0 0"
        rpy="0 0 0" />
      <geometry>
        <mesh
          filename="package://jetcobot_description/meshes/LInk_2.stl" />
      </geometry>
      <material
        name="">
        <color
          rgba="1 1 1 1" />
      </material>
    </visual>
    <collision>
      <origin
        xyz="0 0 0"
        rpy="0 0 0" />
      <geometry>
        <mesh
          filename="package://jetcobot_description/meshes/LInk_2.stl" />
      </geometry>
    </collision>
  </link>
  <joint
    name="2_Joint"
    type="revolute">
    <origin
      xyz="-2.56344886174708E-05 -0.0349999906124702 0.06"
      rpy="0 0 0" />
    <parent
      link="1_Link" />
    <child
      link="2_Link" />
    <axis
      xyz="0 -1 0" />
    <limit
      lower="-2.87"
      upper="2.87"
      effort="0"
      velocity="0" />
  </joint>
  <link
    name="3_Link">
    <inertial>
      <origin
        xyz="1.6839879676764E-05 0.023294180860769 0.0437213142176436"
        rpy="0 0 0" />
      <mass
        value="0.0533199813011819" />
      <inertia
        ixx="9.73800220777058E-05"
        ixy="4.03928474755798E-09"
        ixz="9.626338081533E-09"
        iyy="0.000101574874298831"
        iyz="-4.03698497989361E-06"
        izz="1.36929060248111E-05" />
    </inertial>
    <visual>
      <origin
        xyz="0 0 0"
        rpy="0 0 0" />
      <geometry>
        <mesh
          filename="package://jetcobot_description/meshes/LInk_3.stl" />
      </geometry>
      <material
        name="">
        <color
          rgba="1 1 1 1" />
      </material>
    </visual>
    <collision>
      <origin
        xyz="0 0 0"
        rpy="0 0 0" />
      <geometry>
        <mesh
          filename="package://jetcobot_description/meshes/LInk_3.stl" />
      </geometry>
    </collision>
  </link>
  <joint
    name="3_Joint"
    type="revolute">
    <origin
      xyz="0 0.00678999562722426 0.109999999944807"
      rpy="0 0 0" />
    <parent
      link="2_Link" />
    <child
      link="3_Link" />
    <axis
      xyz="0 -1 0" />
    <limit
      lower="-2.87"
      upper="2.87"
      effort="0"
      velocity="0" />
  </joint>
  <link
    name="4_Link">
    <inertial>
      <origin
        xyz="-4.84201074579515E-06 -0.0230260014326339 0.0076796931512822"
        rpy="0 0 0" />
      <mass
        value="0.0240531902650696" />
      <inertia
        ixx="9.31854762217622E-06"
        ixy="6.04168630160668E-10"
        ixz="3.4137552727643E-09"
        iyy="7.73418506337023E-06"
        iyz="3.30830574244328E-06"
        izz="7.81256309739935E-06" />
    </inertial>
    <visual>
      <origin
        xyz="0 0 0"
        rpy="0 0 0" />
      <geometry>
        <mesh
          filename="package://jetcobot_description/meshes/LInk_4.stl" />
      </geometry>
      <material
        name="">
        <color
          rgba="1 1 1 1" />
      </material>
    </visual>
    <collision>
      <origin
        xyz="0 0 0"
        rpy="0 0 0" />
      <geometry>
        <mesh
          filename="package://jetcobot_description/meshes/LInk_4.stl" />
      </geometry>
    </collision>
  </link>
  <joint
    name="4_Joint"
    type="revolute">
    <origin
      xyz="0 -0.00134543437627838 0.0959999996761873"
      rpy="0 0 0" />
    <parent
      link="3_Link" />
    <child
      link="4_Link" />
    <axis
      xyz="0 -1 0" />
    <limit
      lower="-2.87"
      upper="2.87"
      effort="0"
      velocity="0" />
  </joint>
  <link
    name="5_Link">
    <inertial>
      <origin
        xyz="0.000920147444179747 -8.87115340001549E-05 0.0288537732000537"
        rpy="0 0 0" />
      <mass
        value="0.0314577601971656" />
      <inertia
        ixx="1.33683459564198E-05"
        ixy="2.60891660423066E-08"
        ixz="-2.99675037743924E-06"
        iyy="1.32866723243173E-05"
        iyz="1.65645962236069E-08"
        izz="8.52777440880247E-06" />
    </inertial>
    <visual>
      <origin
        xyz="0 0 0"
        rpy="0 0 0" />
      <geometry>
        <mesh
          filename="package://jetcobot_description/meshes/LInk_5.stl" />
      </geometry>
      <material
        name="">
        <color
          rgba="1 1 1 1" />
      </material>
    </visual>
    <collision>
      <origin
        xyz="0 0 0"
        rpy="0 0 0" />
      <geometry>
        <mesh
          filename="package://jetcobot_description/meshes/LInk_5.stl" />
      </geometry>
    </collision>
  </link>
  <joint
    name="5_Joint"
    type="revolute">
    <origin
      xyz="-2.51335035583085E-05 -0.0335399905878049 0.0348292449246146"
      rpy="0 0 0" />
    <parent
      link="4_Link" />
    <child
      link="5_Link" />
    <axis
      xyz="0 0 1" />
    <limit
      lower="-2.87"
      upper="2.87"
      effort="0"
      velocity="0" />
  </joint>
  <link
    name="6_Link">
    <inertial>
      <origin
        xyz="0.00719200131540984 -7.65911084783799E-06 3.05896694446917E-06"
        rpy="0 0 0" />
      <mass
        value="0.00770526463879312" />
      <inertia
        ixx="1.35526258323655E-06"
        ixy="-5.85324410888035E-10"
        ixz="5.99325370891833E-11"
        iyy="8.40446638273888E-07"
        iyz="-2.43816134145291E-10"
        izz="8.40443397022734E-07" />
    </inertial>
    <visual>
      <origin
        xyz="0 0 0"
        rpy="0 0 0" />
      <geometry>
        <mesh
          filename="package://jetcobot_description/meshes/LInk_6.stl" />
      </geometry>
      <material
        name="">
        <color
          rgba="1 1 1 1" />
      </material>
    </visual>
    <collision>
      <origin
        xyz="0 0 0"
        rpy="0 0 0" />
      <geometry>
        <mesh
          filename="package://jetcobot_description/meshes/LInk_6.stl" />
      </geometry>
    </collision>
  </link>
  <joint
    name="6_Joint"
    type="revolute">
    <origin
      xyz="0.0319651869150594 -2.83148869312522E-05 0.03992044757551"
      rpy="0.785398 0 0" />
    <parent
      link="5_Link" />
    <child
      link="6_Link" />
    <axis
      xyz="1 0 0" />
    <limit
      lower="-3.05"
      upper="3.05"
      effort="0"
      velocity="0" />
  </joint>
  <link
    name="camera_link">
    <inertial>
      <origin
        xyz="-0.00275231085999596 -0.000213763964140273 0.00241270444256747"
        rpy="0 0 0" />
      <mass
        value="0.0173158610148997" />
      <inertia
        ixx="3.93857833594377E-06"
        ixy="5.78200746595397E-09"
        ixz="3.48752198317634E-07"
        iyy="2.77644660480074E-06"
        iyz="1.7431869934464E-09"
        izz="2.12940000335535E-06" />
    </inertial>
    <visual>
      <origin
        xyz="0 0 0"
        rpy="0 0 0" />
      <geometry>
        <mesh
          filename="package://jetcobot_description/meshes/camera_Link.STL" />
      </geometry>
      <material
        name="">
        <color
         rgba="1 1 1 1" />
      </material>
    </visual>
    <collision>
      <origin
        xyz="0 0 0"
        rpy="0 0 0" />
      <geometry>
        <mesh
          filename="package://jetcobot_description/meshes/camera_Link.STL" />
      </geometry>
    </collision>
  </link>
  <joint
    name="camera_Joint"
    type="fixed">
    <origin
      xyz="0.033 0 0.035"
      rpy="0 0 0" />
    <parent
      link="6_Link" />
    <child
      link="camera_link" />
    <axis
      xyz="0 0 0" />
  </joint>
  <link name="gripper_base">
    <visual>
      <geometry>
       <!--- 0.0 0 -0.04 -->
       <mesh filename="package://jetcobot_description/meshes/gripper_base.dae"/>
      </geometry>
    <origin xyz = "0.0 0 -0.012 " rpy = " 0 0 0"/>
    </visual>
    <collision>
      <geometry>
       <!--- 0.0 0 -0.04 -->
       <mesh filename="package://jetcobot_description/meshes/gripper_base.dae"/>
      </geometry>
    <origin xyz = "0.0 0 -0.012 " rpy = " 0 0 0"/>
    </collision>
  </link>

  <link name="gripper_left1">
    <visual>
      <geometry>
       <!--- 0.0 0 -0.04 -->
       <mesh filename="package://jetcobot_description/meshes/gripper_left1.dae"/>
      </geometry>
    <origin xyz = "0.039 -0.0133 -0.012 " rpy = " 0 0 0"/>
    <!-- <origin xyz = "0.0 0 -0.012 " rpy = " 0 0 0"/> -->
    </visual>
    <collision>
      <geometry>
       <mesh filename="package://jetcobot_description/meshes/gripper_left1.dae"/>
      </geometry>
        <origin xyz = "0.039 -0.0133 -0.012 " rpy = " 0 0 0"/>
    </collision>
  </link>

  <link name="gripper_left2">
    <visual>
      <geometry>
       <mesh filename="package://jetcobot_description/meshes/gripper_left2.dae"/>
      </geometry>
    <origin xyz = "0.005 -0.0195 -0.012 " rpy = " 0 0 0"/>
    </visual>
    <collision>
      <geometry>
       <mesh filename="package://jetcobot_description/meshes/gripper_left2.dae"/>
      </geometry>
        <origin xyz = "0.005 -0.0195 -0.012 " rpy = " 0 0 0"/>
    </collision>
  </link>

  <link name="gripper_left3">
    <visual>
      <geometry>
       <mesh filename="package://jetcobot_description/meshes/gripper_left3.dae"/>
      </geometry>
    <origin xyz = "0.012 0.0025 -0.012 " rpy = " 0 0 0"/>
    <!-- <origin xyz = "0.0 0 0 " rpy = " 0 0 0"/> -->

    </visual>
    <collision>
      <geometry>
       <mesh filename="package://jetcobot_description/meshes/gripper_left3.dae"/>
      </geometry>
    <origin xyz = "0.012 0.0025 -0.012 " rpy = " 0 0 0"/>
    </collision>
  </link>

  <link name="gripper_right1">
    <visual>
      <geometry>
       <mesh filename="package://jetcobot_description/meshes/gripper_right1.dae"/>
      </geometry>
    <origin xyz = "-0.039 -0.0133 -0.012 " rpy = " 0 0 0"/>
    </visual>
    <collision>
      <geometry>
       <mesh filename="package://jetcobot_description/meshes/gripper_right1.dae"/>
      </geometry>
        <origin xyz = "-0.039 -0.0133 -0.012 " rpy = " 0 0 0"/>
    </collision>
  </link>

  <link name="gripper_right2">
    <visual>
      <geometry>
       <mesh filename="package://jetcobot_description/meshes/gripper_right2.dae"/>
      </geometry>
    <origin xyz = "-0.005 -0.0195 -0.012 " rpy = " 0 0 0"/>
    </visual>
    <collision>
      <geometry>
       <mesh filename="package://jetcobot_description/meshes/gripper_right2.dae"/>
      </geometry>
        <origin xyz = "-0.005 -0.0195 -0.012 " rpy = " 0 0 0"/>
    </collision>
  </link>

  <link name="gripper_right3">
    <visual>
      <geometry>
       <mesh filename="package://jetcobot_description/meshes/gripper_right3.dae"/>
      </geometry>
    <origin xyz = "-0.012 0.0025 -0.012 " rpy = " 0 0 0"/>
    </visual>
    <collision>
      <geometry>
       <mesh filename="package://jetcobot_description/meshes/gripper_right3.dae"/>
      </geometry>
    <origin xyz = "-0.012 0.0025 -0.012" rpy = " 0 0 0"/>
    </collision>
  </link>

  <joint name="6_Link_to_gripper_base" type="fixed">
    <!-- <axis xyz="0 0 1"/>
    <limit effort = "1000.0" lower = "-3.14" upper = "3.14159" velocity = "0"/> -->
    <parent link="6_Link"/>
    <child link="gripper_base"/>
    <!-- <origin xyz= "0 0.0 0" rpy = "-1.5708 0 0"/>   -->
    <origin xyz= "0.045 0 0" rpy = "3.141592653589793 0 1.570796326794897"/>  
  </joint>

  <joint name="gripper_controller" type="revolute">
    <axis xyz="0 0 1"/>
    <limit effort = "1000.0" lower = "-0.7" upper = "0.15" velocity = "0"/>
    <parent link="gripper_base"/>
    <child link="gripper_left3"/>
    <origin xyz= "-0.012 -0.0025 0" rpy = "0 0 0"/> 
  </joint>

  <joint name="gripper_base_to_gripper_left2" type="revolute">
    <axis xyz="0 0 1"/>
    <limit effort = "1000.0" lower = "-0.8" upper = "0.5" velocity = "0"/>
    <parent link="gripper_base"/>
    <child link="gripper_left2"/>
    <origin xyz= "-0.005 0.0195 0" rpy = "0 0 0"/> 
    <mimic joint="gripper_controller" multiplier="1.0" offset="0" />
  </joint>

  <joint name="gripper_left3_to_gripper_left1" type="revolute">
    <axis xyz="0 0 1"/>
    <limit effort = "1000.0" lower = "-0.5" upper = "0.5" velocity = "0"/>
    <parent link="gripper_left3"/>
    <child link="gripper_left1"/>
    <origin xyz= "-0.027 0.016 0" rpy = "0 0 0"/> 
    <mimic joint="gripper_controller" multiplier="-1.0" offset="0" />
  </joint>


  <joint name="gripper_base_to_gripper_right3" type="revolute">
    <axis xyz="0 0 1"/>
    <limit effort = "1000.0" lower = "-0.15" upper = "0.7" velocity = "0"/>
    <parent link="gripper_base"/>
    <child link="gripper_right3"/>
    <origin xyz= "0.012 -0.0025 0" rpy = "0 0 0"/> 
    <mimic joint="gripper_controller" multiplier="-1.0" offset="0" />
  </joint>

  <joint name="gripper_base_to_gripper_right2" type="revolute">
    <axis xyz="0 0 1"/>
    <limit effort = "1000.0" lower = "-0.5" upper = "0.8" velocity = "0"/>
    <parent link="gripper_base"/>
    <child link="gripper_right2"/>
    <origin xyz= "0.005 0.0195 0" rpy = "0 0 0"/> 
    <mimic joint="gripper_controller" multiplier="-1.0" offset="0" />
  </joint>

  <joint name="gripper_right3_to_gripper_right1" type="revolute">
    <axis xyz="0 0 1"/>
    <limit effort = "1000.0" lower = "-0.5" upper = "0.5" velocity = "0"/>
    <parent link="gripper_right3"/>
    <child link="gripper_right1"/>
    <origin xyz= "0.027 0.016 0" rpy = "0 0 0"/> 
    <mimic joint="gripper_controller" multiplier="1.0" offset="0" />
  </joint>
</robot>